<?xml version="1.0"?>
<robot xmlns:xacro="http://ros.org/wiki/xacro">

  <!-- Define the revolute joint -->
  <joint name="joint3" type="revolute">
    <parent link="link2"/>  <!-- Parent link is link1 -->
    <child link="link3"/>   <!-- Child link is link2 -->
    
    <!-- Joint Origin -->
    <origin xyz="0.0014 -0.01042 0.096" rpy="0 0 0"/> <!-- Position along Y axis of link1 -->
    
    <!-- Axis of Rotation: Y-axis -->
    <axis xyz="1 0 0"/>  <!-- Revolving around Y-axis -->
    
    <!-- Joint Limits -->
    <limit lower="-1.57" upper="1.57" effort="5" velocity="1"/>
  </joint>


  <transmission name="joint3_trans">
    <type>transmission_interface/SimpleTransmission</type>
    <joint name="joint3">
      <hardwareInterface>EffortJointInterface</hardwareInterface>
    </joint>
    <actuator name="joint3_motor">
      <mechanicalReduction>1</mechanicalReduction>
    </actuator>
  </transmission>

</robot>
